Workbook

Sheet Proyectos SIF
B1: PROYECTOS SIF
B2: Municipio | C2: Subregión | D2: Indicador PDD | E2: N° Contrato/Convenio/BPIN | F2: Proyecto/ Actividad | G2: Descripción/Alcance | H2: Alcance | I2: Mapa | J2: Paquete | K2: Aporte Departamento | L2: Aporte Municipio | M2: Valor Total Proyecto | N2: Fuente Financiación | O2: Modalidad Contratación | P2: Vigencia | Q2: Estado | R2: Fecha de Inicio | S2: Fecha de Terminación | T2: % Avance | U2: Comentarios/Alertas
A3: 1 | B3: Abejorral | C3: Oriente | D3: RVS | E3: 4600018900 | F3: Mantenimiento por Estabilización | G3: Abejorral - Santa Barbara L= 23,77 km | H3: 23.77 | I3: Sí | J3: Estabilización | K3: 20453866674 | L3: 0 | M3: =+K3 -> 20453866674 | N3: Recursos Propios | O3: Contratación Directa | P3: 2025 | Q3: En ejecución | R3: 46174 | S3: 46497 | T3: 0.0066 | U3: Actividades preliminares Topografía, Expolaración geotécnica
B4: Abejorral | C4: Oriente | D4: RVS | E4: 4600018900 | F4: Mantenimiento por Estabilización | G4: Abejorral - La Frontera L=25,49 km | H4: 20.26 | I4: Sí | J4: Estabilización | K4: 23070485659 | L4: 0 | M4: =+K4 -> 23070485659 | N4: Recursos Propios | O4: Contratación Directa | P4: 2025 | Q4: En ejecución | R4: 46174 | S4: 46497 | T4: 0.001 | U4: Actividades preliminares Topografía, Expolaración geotécnica
B5: Abejorral | C5: Oriente | D5: RVU | E5: 2022003050018 | F5: Mejoramiento de las vías urbanas en los municipios de Abejorral y Sonsón | G5: 2,06 km | H5: 2.06 | K5: 4.4514491e+09 | L5: 695573310 | M5: =+K5+L5 -> 5.1470224e+09 | N5: Regalías | O5: Contratación Directa | P5: 2022 | Q5: Terminado | T5: 0.96 | U5: Información tomada de Gesproy. Proyecto que se inició en la administración anterior
B6: Abriaquí | C6: Occidente | D6: RVT | E6: 2019000040080 | F6: Mejoramiento de vías terciarias de los municipios del Occidente | G6: Abriaquí- Vía Quimulá | K6: 23880402999 | L6: 0 | M6: =+K6 -> 23880402999 | N6: Regalías | O6: Contratación Directa | P6: 2019 | Q6: En ejecución | T6: 0.8923
A7: 2 | B7: Abriaquí | C7: Occidente | D7: RVS | F7: Pavimentación Abriaquí-Frontino ( siniestro) | G7: Siniestro
B8: Abriaquí | C8: Occidente | D8: Equipamiento | E8: 4600015639 | F8: Adecuación y mejoramiento del parque principal | G8: 1659 m2 | K8: 1500000000 | L8: 234476838 | M8: =+K8+L8 -> 1734476838 | N8: Recursos Propios | O8: Convenio | P8: 2023 | Q8: Terminado | T8: 1
B9: Abriaquí | C9: Occidente | D9: RVS | E9: 4600014453 | F9: Mejoramiento, actividades y obras complementarias sobre el corredor vial Buenos Aires ( Cañargordas)- Abriaquí | G9: 10 km | H9: 10 | I9: Sí | J9: Mejoramiento | K9: 43458000000 | L9: 0 | M9: =+K9 -> 43458000000 | N9: Recursos Propios | O9: Convenio | P9: 2024 | Q9: En ejecución | T9: 0.92
B10: Abriaquí | C10: Occidente | D10: RVS | E10: 4600018738 | F10: Mejoramiento, actividades y obras complementarias sobre el corredor vial Buenos Aires ( Cañargordas)- Abriaquí | G10: 7,9 km | H10: 7.9 | I10: Sí | J10: Mejoramiento | K10: 6069000000 | L10: 0 | M10: =+K10 -> 6069000000 | N10: Recursos Propios | O10: Contratación Directa | P10: 2025 | Q10: En ejecución | U10: Vías Antioquia
A11: 3 | B11: Alejandría | C11: Oriente | D11: RVS | E11: 4600018900 | F11: Mantenimiento por estabilización | G11: San Rafael -San Roque Santo Domingo - Alejandría: L=25,72 km | H11: 2.26 | I11: Sí | J11: Estabilización | K11: =+'Estabilización datos '!G3*2.26 -> 3.8994714e+09 | L11: 0 | M11: =+K11 -> 3.8994714e+09 | N11: Recursos Propios | O11: Contratación Directa | P11: 2025 | Q11: En ejecución | T11: 0 | U11: Actividades preliminares Topografía, Expolaración geotécnica
B12: Alejandría | C12: Oriente | D12: E & D | E12: N/A | F12: Estudios y diseños OXI- Mantenimiento por Estabilización | G12: Santo Domingo- Alejandría: L= 5 km | H12: 5 | J12: E & D | K12: 6892222466 | L12: 0 | M12: =+K12 -> 6892222466 | N12: Recursos Propios | O12: Conratación Directa | P12: 2025 | Q12: En ejecución | T12: 0.03
B13: Alejandría | C13: Oriente | D13: RVU | E13: 4600017869 | F13: Pavimento Rígido- Vereda La Pava | G13: 0,75 km | H13: 0.75 | K13: 1640831632 | L13: 410207908 | M13: =+K13+L13 -> 2051039540 | N13: Recursos Propios | O13: Convenio | P13: 2025 | Q13: Terminado | T13: 1 | U13: Terminado 2025
B14: Alejandría | C14: Oriente | D14: RVT | E14: 25AS111B2696 | F14: Placa huella- Vía San José | G14: 0,3 km | H14: 0.3 | K14: 105000000 | L14: 292159565 | M14: =+L14+K14 -> 397159565 | N14: Materiales | O14: Convenio | P14: 2025 | Q14: Terminado | T14: 1 | U14: Terminado 2026
B15: Alejandría | C15: Oriente | D15: RVT | E15: 2025003050047 | F15: Placa huella | G15: 1 km | H15: 1 km | J15: Mejoramiento | K15: 2577210949 | L15: 0 | M15: =+K15 -> 2577210949 | N15: Regalías | O15: Contratación directa | P15: 2026 | Q15: En ejecución | T15: 0.23
B16: Alejandría | C16: Oriente | D16: RVT | E16: 24AS111B1776 | F16: Placa Huella | G16: 1 km | H16: 1 | K16: 349992727 | L16: 603615690 | M16: =+K16+L16 -> 953608417 | N16: Materiales | O16: Convenio | P16: 2024 | Q16: Terminado | T16: 1 | U16: Terminado 2024
B17: Amagá | C17: Suroeste | D17: RVS | E17: N/A | F17: Amagá-Angelopolis | G17: 11,2 km | H17: 11.2 | I17: Sí | J17: Mejoramiento
A18: 4 | B18: Amagá | C18: Suroeste | D18: RVT | E18: 2025003050003 | F18: Placa huella en las veredas Pueblitos la Delgadita, Malabrigo y Maní del Cardal | G18: 3,5 km | H18: 3.5 | I18: No | J18: Mejoramiento | K18: 4519742225 | L18: =+M18-K18 -> 1061912850 | M18: 5581655075 | N18: Regalías | O18: Contratación Directa | P18: 2025 | Q18: En ejecución | T18: 0.87
B19: Amalfi | C19: Nordeste | D19: RVT | E19: 2020000040028 | F19: Mejoramiento de Vías Rurales en los Municipios de Amalfi Remedios Vegachí y Yalí | G19: 3,3 km | H19: 3.3 | I19: No | J19: Mejoramiento | K19: 22647234828 | L19: 0 | M19: =+K19 -> 22647234828 | N19: Regalías | O19: Contratación Directa | P19: 2020 | Q19: En ejecución | T19: 0.6775 | U19: Información tomada de Gesproy. Proyecto que se inició en la administración anterior
A20: 5 | B20: Amalfi | C20: Nordeste | D20: RVS | E20: 23OO111B1457 | F20: Mejoramiento de las vías del GRUPO 1 de Circuitos Estratégicos del Departamento de Antioquia. LOTE 2: Nordeste | G20: Playas - Portachuelo - Chorritos- Amalfi (62AN21-4): L=1 km | H20: 1 | I20: Sí | J20: Mejoramiento | K20: 5175635183 | L20: 0 | M20: =+K20 -> 5175635183 | N20: Recursos Propios | O20: Licitación Pública | P20: 2023 | Q20: Terminado | T20: 1 | U20: Terminado 2024
B21: Amalfi | C21: Nordeste | D21: RVS | E21: N/A | F21: Mejoramiento de la vía entre el casco Urbano del Municipio de Amalfi y la vereda Chorritos. | G21: 5.87 | H21: 5.87 | I21: Sí | J21: Mejoramiento | K21: =+M21 -> 36179479644 | M21: 36179479644 | N21: OXI | O21: N/A | P21: 2025 | Q21: Por iniciar | T21: 0 | U21: Pendiente designación supervisor por parte de INVIAS
C22: Nordeste | D22: RVS | E22: 4600018883 | F22: Mantenimiento por estabilización | G22: Amalfi - Portachuelos - Santa Isabel: L=10 km | H22: 10 | I22: Sí | J22: Estabilización | K22: =+'Estabilización datos '!G8*10 -> 1.1470832e+10 | L22: 0 | M22: =+K22 -> 1.1470832e+10 | N22: Recursos Propios | O22: Licitación Pública | P22: 2025 | Q22: En ejecución | U22: En ejecución de actividades de topografía y ensayos de laboratorio
B23: Amalfi | C23: Nordeste | D23: RVT | E23: 2024003050241 | F23: Placa huella en la vereda Guayabito y el Táparo | G23: 2 km | H23: 2 | I23: No | J23: Mejoramiento | K23: 3.3857047e+09 | L23: 8.4642619e+08 | M23: 4232130933 | N23: Regalías | O23: Contratación Directa | P23: 2024 | Q23: En ejecución | T23: 0.18
A24: 6 | B24: Andes | C24: Suroeste | D24: RVS | E24: 25OO111B2824 | F24: Mantenimiento por estabilización | G24: Andes - San José - Pueblorrico: L=22,39 km | H24: 23.39 | I24: Sí | J24: Estabilización | K24: =1341963493*22.39 -> 3.0046563e+10 | L24: 0 | M24: =+K24 -> 3.0046563e+10 | N24: Recursos Propios | O24: Licitación Pública | P24: 2025 | Q24: En ejecución | U24: En ejecución de actividades de topografía y ensayos de laboratorio
B25: Andes | C25: Suroeste | D25: RVT | E25: 24AS111B2029 | F25: Placa Huella | G25: 1km | H25: 1 | K25: 350000000 | L25: 487439836 | M25: =+K25+L25 -> 837439836 | N25: Materiales | O25: Convenio | P25: 2024 | Q25: Terminado | T25: 1 | U25: Terminado 2026
B26: Andes | C26: Suroeste | D26: RVS | E26: 4600017302 | F26: Estudios y diseños Fase III, destinados a la intervención de la vía La Ye a la Bodega- Buenos Aires | G26: 9,2 km | H26: 9.2 | K26: 149755110 | L26: 321685399 | M26: =+K26+L26 -> 471440509 | N26: Recursos Propios | O26: Convenio | P26: 2024 | Q26: Terminado | T26: 1 | U26: Terminado
B27: Andes | C27: Suroeste | D27: RVS | E27: 26OO111B2863 | F27: Mejoramiento vía La Ye a La Bodega (Andes) - Buenos Aires | G27: 9,2 km | H27: 9.2 | I27: Sí | J27: Mejoramiento | K27: 22480950715 | L27: 0 | M27: =+K27 -> 22480950715 | N27: Regalías | O27: Licitación Pública | P27: 2025 | Q27: Por iniciar | U27: Adjudicado
B28: Andes | C28: Suroeste | D28: Espacio Público | E28: 4600014774 | F28: Parque La Chaparrala | G28: 14373 m2 | K28: 4500000000 | L28: =+M28-K28 -> 1316681148 | M28: 5816681148 | N28: Recursos Propios | O28: Convenio | P28: 2022 | Q28: Terminado | T28: 1 | U28: Terminado 2025
B29: Andes | C29: Suroeste | D29: RVT | E29: 24AS111B2047 | F29: Mejoramiento mediante enrocado | G29: 0,25 km | H29: 0.25 | K29: 496038085 | L29: 0 | M29: =1984152341/4 -> 4.9603809e+08 | N29: Recursos Propios | O29: Convenio | P29: 2025 | Q29: Teminado | T29: 1 | U29: Suspendido hasta el 29/03/2026
B30: Andes | C30: Suroeste | D30: Espacio Público | E30: N/A | F30: Proyecto PAISA en Andes | G30: Cancha emblemática y mobiliario lúdico | K30: 100000000 | L30: 50000000 | M30: =+K30+L30 -> 150000000 | N30: Recursos Propios | O30: Convenio | P30: 2025 | Q30: En estructuración | U30: En estructuración
B31: Andes | C31: Suroeste | D31: Valorización | E31: 4600017793 | F31: Estudios y diseños, destinados a la intervención de corredores viales del Departamento de Antioquia | G31: Tapartó (Andes): L= 21,57 km | H31: 21.57 | I31: Sí | J31: Valorización | K31: 17166424376 | L31: 0 | M31: =+K31 -> 17166424376 | N31: Recursos Propios | O31: Contratación directa | P31: 2024 | Q31: En ejecución | U31: El valor total corresponde al valor de todo el convenio de estudios y diseños de los 14 corredores de valorización
B32: Andes | C32: Suroeste | D32: Valorización | E32: 4600017793 | F32: Estudios y diseños de vías a intervenir por Valorización | G32: Jericó-Buenos Aires- La Bodega ( Andes): L= 16,45 | H32: 2.66 | I32: Sí | J32: Valorización | K32: 17166424376 | L32: 0 | M32: =+K32 -> 17166424376 | N32: Recursos Propios | O32: Contratación directa | P32: 2024 | Q32: En ejecución | T32: 0.87 | U32: El valor total corresponde al valor de todo el convenio de estudios y diseños de los 14 corredores de valorización
B33: Andes | C33: Suroeste | D33: RVT | E33: 25AS111B2781 | F33: Placa huella JAC Vereda La Solita | G33: 0,2 km | H33: 0.2 | K33: 223022690 | L33: 24056079 | M33: =+K33+L33 -> 247078769 | N33: Recursos Propios | O33: Convenio | P33: 2025 | Q33: Terminado | T33: 1 | U33: Terminado 2026
B34: Andes | C34: Suroeste | D34: RVT | E34: 2024003050237 | F34: Placa huella Santa Rita | G34: 6 km | H34: 6 | I34: No | J34: Mejoramiento | K34: 9359210977 | L34: 2311092391 | M34: =+K34+L34 -> 11670303368 | N34: Regalías | O34: Contratación Directa | P34: 2025 | Q34: Terminado | T34: 1 | U34: Terminado 2026
B35: Angelópolis | C35: Suroeste | D35: RVS | F35: Amagá-Angelopolis | G35: Siniestro | H35: Siniestro
B36: Angelópolis | C36: Suroeste | D36: RVT | E36: 24AS111B1979 | F36: Placa Huella | G36: 1 km | H36: 1 | K36: 264662480 | L36: 364897398 | M36: 830315725 | N36: Cafeteros / Materiales | O36: Convenio | P36: 2024 | Q36: Terminado | T36: 1
B37: Angostura | C37: Norte | D37: RVS | E37: 24OO111B1661 | F37: Mejoramiento de las vías del GRUPO 3 de Circuitos Estratégicos del Departamento Antioquia | G37: Vía La Ese - Angostura - La Ye (Partidas a Angostura) - La Herradura L=2,00 Km | H37: 2 | I37: Sí | J37: Mejoramiento | K37: 7842065818 | L37: 0 | M37: 7842065818 | N37: Recursos Propios | O37: Licitación Pública | P37: 2024 | Q37: Terminado | T37: 1 | U37: Terminado 2025
A38: 8 | B38: Angostura | C38: Norte | D38: RVS | E38: 46000018883 | F38: Mantenimiento por estabilización | G38: Carolina del Príncipe Angostura: L=13,62 km | H38: 13.62 | I38: Sí | J38: Estabilización | K38: =1341407247*13.62 -> 1.8269967e+10 | L38: 0 | M38: =+K38 -> 1.8269967e+10 | N38: Recursos Propios | O38: Licitación Pública | P38: 2025 | Q38: En ejecución | U38: En actividades preliminares
B39: Angostura | C39: Norte | D39: RVT | E39: 2025003050057 | F39: Placa huella Matablanco | G39: 1 km | H39: 1 | I39: No | J39: Mejoramiento | K39: 2205897938 | L39: 0 | M39: =+K39 -> 2205897938 | N39: Regalías | O39: Contratación directa | P39: 2025 | Q39: Por iniciar | T39: 0 | U39: Sin contratar
B40: Angostura | C40: Norte | D40: RVT | E40: 24AS111B1979 | F40: Placa Huella | G40: 1 km | H40: 1 | I40: No | K40: 265194900 | L40: 463744518 | M40: 913939418 | N40: Cafeteros / Materiales | O40: Convenio | P40: 2024 | Q40: Terminado | T40: 1 | U40: Se ejecutaron 1,26 km
...

Sheet Estabilización datos 
B2: ESTABILIZACIÓN | D2: VALOR OBRA | E2: VALOR INTERVENTORÍA | F2: km | G2: VALOR POR km
B3: LOTE 1 | C3: ORIENTE | D3: 108554215084 | E3: 58743460670 | F3: 96.96 | G3: =(+D3+E3)/F3 -> 1.7254298e+09 | H3: 1292280517
B4: LOTE 2 | C4: OCCIDENTE | D4: 104855613958 | E4: 7853059284 | F4: 94.95 | G4: =(+D4+E4)/F4 -> 1.1870318e+09 | I4: =+H3*5.33 -> 6.8878552e+09
B5: LOTE 3 | C5: URABÁ | D5: 144973755369 | E5: 9595864128 | F5: 120.65 | G5: =(+D5+E5)/F5 -> 1.2811407e+09
B6: LOTE 4 | C6: MAGDALENA MEDIO | D6: 54441800920 | E6: 4769992.8 | F6: 55 | G6: =(+D6+E6)/F6 -> 9.8993765e+08
B7: LOTE 5 | C7: SUROESTE | D7: 72870090400 | E7: 5960752013 | F7: 68.26 | G7: =(+D7+E7)/F7 -> 1.1548614e+09
B8: LOTE 6 | C8: NORDESTE | D8: 57385592096 | E8: 4671608128 | F8: 54.1 | G8: =(+D8+E8)/F8 -> 1.1470832e+09
B9: LOTE 7 | C9: BAJO CAUCA | D9: 26362070969 | E9: 1854347722 | F9: 25 | G9: =(+D9+E9)/F9 -> 1.1286567e+09
B10: LOTE 8 | C10: NORTE | D10: 124487403196 | E10: 9498182082 | F10: 117.25 | G10: =(+D10+E10)/F10 -> 1.1427342e+09
